2023-10-09 09:54:47,765 INFO    MainThread:3089905 [internal.py:wandb_internal():92] W&B internal server running at pid: 3089905, started at: 2023-10-09 09:54:47.765721
2023-10-09 09:54:47,767 DEBUG   HandlerThread:3089905 [handler.py:handle_request():131] handle_request: check_version
2023-10-09 09:54:47,767 INFO    WriterThread:3089905 [datastore.py:open_for_write():77] open: /home/tg22/remote-pycharm/plant/training/PlanT/outputs/training/DEBUG/2023-10-09_09-53-21/wandb/run-20231009_095447-5x5sqhj2/run-5x5sqhj2.wandb
2023-10-09 09:54:47,769 DEBUG   SenderThread:3089905 [sender.py:send():235] send: header
2023-10-09 09:54:47,770 DEBUG   SenderThread:3089905 [sender.py:send_request():249] send_request: check_version
2023-10-09 09:54:48,133 DEBUG   SenderThread:3089905 [sender.py:send():235] send: run
2023-10-09 09:54:48,138 INFO    SenderThread:3089905 [sender.py:_maybe_setup_resume():490] checking resume status for seqdrive/training/5x5sqhj2
2023-10-09 09:54:48,791 ERROR   SenderThread:3089905 [internal_api.py:execute():143] 404 response executing GraphQL.
2023-10-09 09:54:48,791 ERROR   SenderThread:3089905 [internal_api.py:execute():144] {"errors":[{"message":"project not found","path":["upsertBucket"]}],"data":{"upsertBucket":null}}
2023-10-09 09:54:49,134 INFO    WriterThread:3089905 [datastore.py:close():281] close: /home/tg22/remote-pycharm/plant/training/PlanT/outputs/training/DEBUG/2023-10-09_09-53-21/wandb/run-20231009_095447-5x5sqhj2/run-5x5sqhj2.wandb
2023-10-09 09:54:49,135 INFO    HandlerThread:3089905 [handler.py:finish():739] shutting down handler
2023-10-09 09:54:49,771 ERROR   MainThread:3089905 [internal.py:wandb_internal():164] Thread SenderThread:
Traceback (most recent call last):
  File "/home/tg22/.conda/envs/plant/lib/python3.7/site-packages/wandb/sdk/lib/retry.py", line 102, in __call__
    result = self._call_fn(*args, **kwargs)
  File "/home/tg22/.conda/envs/plant/lib/python3.7/site-packages/wandb/sdk/internal/internal_api.py", line 146, in execute
    six.reraise(*sys.exc_info())
  File "/home/tg22/.conda/envs/plant/lib/python3.7/site-packages/six.py", line 719, in reraise
    raise value
  File "/home/tg22/.conda/envs/plant/lib/python3.7/site-packages/wandb/sdk/internal/internal_api.py", line 140, in execute
    return self.client.execute(*args, **kwargs)
  File "/home/tg22/.conda/envs/plant/lib/python3.7/site-packages/wandb/vendor/gql-0.2.0/gql/client.py", line 52, in execute
    result = self._get_result(document, *args, **kwargs)
  File "/home/tg22/.conda/envs/plant/lib/python3.7/site-packages/wandb/vendor/gql-0.2.0/gql/client.py", line 60, in _get_result
    return self.transport.execute(document, *args, **kwargs)
  File "/home/tg22/.conda/envs/plant/lib/python3.7/site-packages/wandb/vendor/gql-0.2.0/gql/transport/requests.py", line 39, in execute
    request.raise_for_status()
  File "/home/tg22/.conda/envs/plant/lib/python3.7/site-packages/requests/models.py", line 943, in raise_for_status
    raise HTTPError(http_error_msg, response=self)
requests.exceptions.HTTPError: 404 Client Error: Not Found for url: https://api.wandb.ai/graphql

During handling of the above exception, another exception occurred:

Traceback (most recent call last):
  File "/home/tg22/.conda/envs/plant/lib/python3.7/site-packages/wandb/apis/normalize.py", line 24, in wrapper
    return func(*args, **kwargs)
  File "/home/tg22/.conda/envs/plant/lib/python3.7/site-packages/wandb/sdk/internal/internal_api.py", line 1296, in upsert_run
    response = self.gql(mutation, variable_values=variable_values, **kwargs)
  File "/home/tg22/.conda/envs/plant/lib/python3.7/site-packages/wandb/sdk/lib/retry.py", line 118, in __call__
    if not check_retry_fn(e):
  File "/home/tg22/.conda/envs/plant/lib/python3.7/site-packages/wandb/util.py", line 821, in no_retry_auth
    raise CommError("Permission denied, ask the project owner to grant you access")
wandb.errors.CommError: Permission denied, ask the project owner to grant you access

During handling of the above exception, another exception occurred:

Traceback (most recent call last):
  File "/home/tg22/.conda/envs/plant/lib/python3.7/site-packages/wandb/sdk/internal/internal_util.py", line 54, in run
    self._run()
  File "/home/tg22/.conda/envs/plant/lib/python3.7/site-packages/wandb/sdk/internal/internal_util.py", line 105, in _run
    self._process(record)
  File "/home/tg22/.conda/envs/plant/lib/python3.7/site-packages/wandb/sdk/internal/internal.py", line 305, in _process
    self._sm.send(record)
  File "/home/tg22/.conda/envs/plant/lib/python3.7/site-packages/wandb/sdk/internal/sender.py", line 237, in send
    send_handler(record)
  File "/home/tg22/.conda/envs/plant/lib/python3.7/site-packages/wandb/sdk/internal/sender.py", line 692, in send_run
    self._init_run(run, config_value_dict)
  File "/home/tg22/.conda/envs/plant/lib/python3.7/site-packages/wandb/sdk/internal/sender.py", line 730, in _init_run
    commit=run.git.last_commit or None,
  File "/home/tg22/.conda/envs/plant/lib/python3.7/site-packages/wandb/apis/normalize.py", line 62, in wrapper
    six.reraise(CommError, CommError(message, err), sys.exc_info()[2])
  File "/home/tg22/.conda/envs/plant/lib/python3.7/site-packages/six.py", line 718, in reraise
    raise value.with_traceback(tb)
  File "/home/tg22/.conda/envs/plant/lib/python3.7/site-packages/wandb/apis/normalize.py", line 24, in wrapper
    return func(*args, **kwargs)
  File "/home/tg22/.conda/envs/plant/lib/python3.7/site-packages/wandb/sdk/internal/internal_api.py", line 1296, in upsert_run
    response = self.gql(mutation, variable_values=variable_values, **kwargs)
  File "/home/tg22/.conda/envs/plant/lib/python3.7/site-packages/wandb/sdk/lib/retry.py", line 118, in __call__
    if not check_retry_fn(e):
  File "/home/tg22/.conda/envs/plant/lib/python3.7/site-packages/wandb/util.py", line 821, in no_retry_auth
    raise CommError("Permission denied, ask the project owner to grant you access")
wandb.errors.CommError: Permission denied, ask the project owner to grant you access
2023-10-09 09:54:51,792 INFO    MainThread:3089905 [internal.py:handle_exit():79] Internal process exited
